Workbook

Sheet Cover
B1: WALMART INC.
B5: Financial Analysis | 2020-2025
B10: Prepared by: Gracie Riner
B12: Project Type: Financial Analysis & DCF Valuation Model
B14: Date: June 2026
B16: Data Source: Walmart 10-K Filings
B18: Analysis Period: Fiscal Years 2020-2025
B22: Contents
B25: Raw Data | D25: Financials sourced from 10-K filings
B26: Ratios & Calculations | D26: Probability and return ratios and DCF Calculations
B27: YoY Growth | D27: Year-over-year and CAGR growth analysis
B28: Peer Comparison | D28: Peer benchmarking
B29: DCF Sensivitity Analysis | D29: WACC vs. FCF Growth Rate
B30: Insights | D30: Key findings, trends, and commentary
B31: Dashboard | D31: Visual summary of financial performance
B38: Key
B41: Bold | C41: = | D41: Calculations
B42: Green on yellow | C42: = | D42: Analyst Assumption
B43: Blue Tabs | C43: = | D43: Core Financial Analysis

Sheet Raw Data
B2: WALMART INC. | Historical Financials ($mm)
B4: Source: Walmart 10-K Filings | All values in USD millions
B6: Metric | C6: 2020 | D6: 2021 | E6: 2022 | F6: 2023 | G6: 2024 | H6: 2025
B7: ($mm)
B8: Revenue | C8: 523964 | D8: 559151 | E8: 572754 | F8: 611289 | G8: 648125 | H8: 680985
B9: Cost of Sales | C9: -394605 | D9: -420315 | E9: -429000 | F9: -463721 | G9: -487837 | H9: -511285
B10: Gross Profit | C10: ='Raw Data'!C8+'Raw Data'!C9 -> 129359 | D10: ='Raw Data'!D8+'Raw Data'!D9 -> 138836 | E10: ='Raw Data'!E8+'Raw Data'!E9 -> 143754 | F10: ='Raw Data'!F8+'Raw Data'!F9 -> 147568 | G10: ='Raw Data'!G8+'Raw Data'!G9 -> 160288 | H10: ='Raw Data'!H8+'Raw Data'!H9 -> 169700
B11: Operating Income | C11: 20568 | D11: 22548 | E11: 25942 | F11: 20428 | G11: 27012 | H11: 29348
B12: Net Income | C12: 15201 | D12: 13706 | E12: 13940 | F12: 11292 | G12: 16270 | H12: 20157
B13: Total Assets | C13: 252496 | D13: 252496 | E13: 244860 | F13: 243197 | G13: 254699 | H13: 260649
B14: Total Equity | C14: 74669 | D14: 80925 | E14: 83861 | F14: 76693 | G14: 91891 | H14: 98123
B15: Total Debt | C15: 51115 | D15: 44309 | E15: 34483 | F15: 37491 | G15: 36132 | H15: 34784
B16: Operating Cash Flow | C16: 25255 | D16: 36074 | E16: 24181 | F16: 28841 | G16: 35726 | H16: 36443
B17: CapEx | C17: 10705 | D17: 10264 | E17: 13106 | F17: 16857 | G17: 20606 | H17: 23783
B18: Interest Expense | C18: 2410 | D18: 2194 | E18: 1836 | F18: 1874 | G18: 2137 | H18: 2245
B19: Pre-Tax Income | C19: 20116 | D19: 20564 | E19: 18696 | F19: 17016 | G19: 21848 | H19: 26309
B20: Income Tax Expense | C20: 4915 | D20: 6858 | E20: 4756 | F20: 5724 | G20: 5578 | H20: 6152
B21: Cash & Cash Equivalents | C21: 9465 | D21: 17741 | E21: 14760 | F21: 8625 | G21: 9867 | H21: 9037
B23: *Calculations in bold font

Sheet Ratios & Calculations
B3: WALMART INC. | Profability and Return Ratios
B5: All ratios calculated from Raw Data sheet
B7: Ratio | C7: 2020 | D7: 2021 | E7: 2022 | F7: 2023 | G7: 2024 | H7: 2025
B9: Gross Margin | C9: ='Raw Data'!C10/'Raw Data'!C8 -> 0.24688528 | D9: ='Raw Data'!D10/'Raw Data'!D8 -> 0.24829787 | E9: ='Raw Data'!E10/'Raw Data'!E8 -> 0.25098733 | F9: ='Raw Data'!F10/'Raw Data'!F8 -> 0.24140464 | G9: ='Raw Data'!G10/'Raw Data'!G8 -> 0.24731032 | H9: ='Raw Data'!H10/'Raw Data'!H8 -> 0.24919785
B10: Operating Margin | C10: ='Raw Data'!C11/'Raw Data'!C8 -> 0.039254605 | D10: ='Raw Data'!D11/'Raw Data'!D8 -> 0.040325422 | E10: ='Raw Data'!E11/'Raw Data'!E8 -> 0.045293442 | F10: ='Raw Data'!F11/'Raw Data'!F8 -> 0.033417909 | G10: ='Raw Data'!G11/'Raw Data'!G8 -> 0.041677146 | H10: ='Raw Data'!H11/'Raw Data'!H8 -> 0.043096397
B11: Net Margin | C11: ='Raw Data'!C12/'Raw Data'!C8 -> 0.029011535 | D11: ='Raw Data'!D12/'Raw Data'!D8 -> 0.024512162 | E11: ='Raw Data'!E12/'Raw Data'!E8 -> 0.024338547 | F11: ='Raw Data'!F12/'Raw Data'!F8 -> 0.018472441 | G11: ='Raw Data'!G12/'Raw Data'!G8 -> 0.025103182 | H11: ='Raw Data'!H12/'Raw Data'!H8 -> 0.029599771
B12: Return on Assets (ROA) | C12: ='Raw Data'!C12/'Raw Data'!C13 -> 0.060202934 | D12: ='Raw Data'!D12/'Raw Data'!D13 -> 0.054282048 | E12: ='Raw Data'!E12/'Raw Data'!E13 -> 0.056930491 | F12: ='Raw Data'!F12/'Raw Data'!F13 -> 0.046431494 | G12: ='Raw Data'!G12/'Raw Data'!G13 -> 0.063879324 | H12: ='Raw Data'!H12/'Raw Data'!H13 -> 0.077333886
B13: Return on Equity (ROE) | C13: ='Raw Data'!C12/'Raw Data'!C14 -> 0.20357846 | D13: ='Raw Data'!D12/'Raw Data'!D14 -> 0.1693667 | E13: ='Raw Data'!E12/'Raw Data'!E14 -> 0.16622745 | F13: ='Raw Data'!F12/'Raw Data'!F14 -> 0.14723638 | G13: ='Raw Data'!G12/'Raw Data'!G14 -> 0.1770576 | H13: ='Raw Data'!H12/'Raw Data'!H14 -> 0.20542584
B14: Debt-to-Equity | C14: ='Raw Data'!C15/'Raw Data'!C14 -> 0.6845545 | D14: ='Raw Data'!D15/'Raw Data'!D14 -> 0.54753167 | E14: ='Raw Data'!E15/'Raw Data'!E14 -> 0.41119233 | F14: ='Raw Data'!F15/'Raw Data'!F14 -> 0.48884514 | G14: ='Raw Data'!G15/'Raw Data'!G14 -> 0.39320499 | H14: ='Raw Data'!H15/'Raw Data'!H14 -> 0.35449385
B16: *Calculations in bold font
B21: WALMART INC. | DCF Calculations
B23: All values calculated from Raw Data sheet
B25: Historical FCF | C25: 2020 | D25: 2021 | E25: 2022 | F25: 2023 | G25: 2024 | H25: 2025
B27: Free Cash Flow | C27: ='Raw Data'!C16-'Raw Data'!C17 -> 14550 | D27: ='Raw Data'!D16-'Raw Data'!D17 -> 25810 | E27: ='Raw Data'!E16-'Raw Data'!E17 -> 11075 | F27: ='Raw Data'!F16-'Raw Data'!F17 -> 11984 | G27: ='Raw Data'!G16-'Raw Data'!G17 -> 15120 | H27: ='Raw Data'!H16-'Raw Data'!H17 -> 12660
B30: Assumptions | C30: Value | D30: Source
B32: Risk-Free Rate | C32: 0.0438 | D32: US Treasury, June 2026
B33: Beta | C33: 0.6 | D33: Yahoo Finance, June 2026
B34: Equity Risk Premium | C34: 0.0423 | D34: Damodaran, NYU Stern, 2026
B35: Cost of Equity | C35: =C32+C33*C34 -> 0.06918 | D35: Calculated -- CAPM formula
B36: Cost of Debt | C36: ='Raw Data'!C18/'Raw Data'!C15 -> 0.047148587 | D36: Calculated
B37: Tax Rate | C37: ='Raw Data'!C20/'Raw Data'!C19 -> 0.24433287 | D37: Calculated
B38: Share Price | C38: 114.75 | D38: Google Finance, June 2026
B39: Shares Outstanding | C39: 8017 | D39: Walmart 10-K FY2025
B40: Market Cap | C40: =C39*C38 -> 919950.75 | D40: Calculated
B41: Debt Weight | C41: ='Raw Data'!H15/('Raw Data'!H15+'Ratios & Calculations'!C40) -> 0.036433156 | D41: Calculated
B42: Equity Weight | C42: =C40/('Raw Data'!H15+'Ratios & Calculations'!C40) -> 0.96356684 | D42: Calculated
B43: WACC | C43: =(C42*C35)+(C41*C36*(1-C37)) -> 0.067957618 | D43: Calculated -- WACC formula
B44: CAGR | C44: =(H27/C27)^(1/5)-1 -> -0.027445064 | D44: Calculated
B45: FCF Growth Rate | C45: 0.075 | D45: Analyst assumption
B46: Terminal Growth Rate | C46: 0.025 | D46: Analyst assumption
B49: DCF Metric | C49: 2026 | D49: 2027 | E49: 2028 | F49: 2029 | G49: 2030
B51: Projected FCF | C51: =H27*(1+$C$45) -> 13609.5 | D51: =C51*(1+$C$45) -> 14630.212 | E51: =D51*(1+$C$45) -> 15727.478 | F51: =E51*(1+$C$45) -> 16907.039 | G51: =F51*(1+$C$45) -> 18175.067
B52: Discount Factor | C52: =1/(1+$C$43)^1 -> 0.93636675 | D52: =1/(1+$C$43)^2 -> 0.87678268 | E52: =1/(1+$C$43)^3 -> 0.82099015 | F52: =1/(1+$C$43)^4 -> 0.76874787 | G52: =1/(1+$C$43)^5 -> 0.71982995
B53: PV of FCF | C53: =C51*C52 -> 12743.483 | D53: =D51*D52 -> 12827.517 | E53: =E51*E52 -> 12912.105 | F53: =F51*F52 -> 12997.251 | G53: =G51*G52 -> 13082.958 | H53: =SUM(C53:G53) -> 64563.313
B57: DCF Outputs
B59: Terminal Value | C59: =G51*(1+$C$46)/($C$43-$C$46) -> 433670.32
B60: PV of Terminal Value | C60: =C59/(1+C43)^5 -> 312168.88
B61: Enterprise Value | C61: =H53+C60 -> 376732.2
B62: Net Debt | C62: ='Raw Data'!H15-'Raw Data'!H21 -> 25747
B63: Equity Value | C63: =C61-C62 -> 350985.2
...

Sheet Sensitivity Analysis
B2: WALMART INC. | Implied Share Price
B4: WACC vs FCF Growth Rate
B6: WACC
B7: FCF Growth Rate | D7: 0.055 | E7: 0.06 | F7: 0.065 | G7: 0.07 | H7: 0.075 | I7: 0.08 | J7: 0.085
C8: 0.04 | D8: =(($G$21*(1+$C8)/(1+D$7)^1) +($G$21*(1+$C8)^2/(1+D$7)^2) +($G$21*(1+$C8)^3/(1+D$7)^3) +($G$21*(1+$C8)^4/(1+D$7)^4) +($G$21*(1+$C8)^5/(1+D$7)^5) +(($G$21*(1+$C8)^5*(1+$G$20)/(D$7-$G$20))/(1+D$7)^5) -$G$23) /$G$24 -> 54.579731 | E8: =(($G$21*(1+$C8)/(1+E$7)^1) +($G$21*(1+$C8)^2/(1+E$7)^2) +($G$21*(1+$C8)^3/(1+E$7)^3) +($G$21*(1+$C8)^4/(1+E$7)^4) +($G$21*(1+$C8)^5/(1+E$7)^5) +(($G$21*(1+$C8)^5*(1+$G$20)/(E$7-$G$20))/(1+E$7)^5) -$G$23) /$G$24 -> 46.293393 | F8: =(($G$21*(1+$C8)/(1+F$7)^1) +($G$21*(1+$C8)^2/(1+F$7)^2) +($G$21*(1+$C8)^3/(1+F$7)^3) +($G$21*(1+$C8)^4/(1+F$7)^4) +($G$21*(1+$C8)^5/(1+F$7)^5) +(($G$21*(1+$C8)^5*(1+$G$20)/(F$7-$G$20))/(1+F$7)^5) -$G$23) /$G$24 -> 40.079134 | G8: =(($G$21*(1+$C8)/(1+G$7)^1) +($G$21*(1+$C8)^2/(1+G$7)^2) +($G$21*(1+$C8)^3/(1+G$7)^3) +($G$21*(1+$C8)^4/(1+G$7)^4) +($G$21*(1+$C8)^5/(1+G$7)^5) +(($G$21*(1+$C8)^5*(1+$G$20)/(G$7-$G$20))/(1+G$7)^5) -$G$23) /$G$24 -> 35.246252 | H8: =(($G$21*(1+$C8)/(1+H$7)^1) +($G$21*(1+$C8)^2/(1+H$7)^2) +($G$21*(1+$C8)^3/(1+H$7)^3) +($G$21*(1+$C8)^4/(1+H$7)^4) +($G$21*(1+$C8)^5/(1+H$7)^5) +(($G$21*(1+$C8)^5*(1+$G$20)/(H$7-$G$20))/(1+H$7)^5) -$G$23) /$G$24 -> 31.380323 | I8: =(($G$21*(1+$C8)/(1+I$7)^1) +($G$21*(1+$C8)^2/(1+I$7)^2) +($G$21*(1+$C8)^3/(1+I$7)^3) +($G$21*(1+$C8)^4/(1+I$7)^4) +($G$21*(1+$C8)^5/(1+I$7)^5) +(($G$21*(1+$C8)^5*(1+$G$20)/(I$7-$G$20))/(1+I$7)^5) -$G$23) /$G$24 -> 28.217626 | J8: =(($G$21*(1+$C8)/(1+J$7)^1) +($G$21*(1+$C8)^2/(1+J$7)^2) +($G$21*(1+$C8)^3/(1+J$7)^3) +($G$21*(1+$C8)^4/(1+J$7)^4) +($G$21*(1+$C8)^5/(1+J$7)^5) +(($G$21*(1+$C8)^5*(1+$G$20)/(J$7-$G$20))/(1+J$7)^5) -$G$23) /$G$24 -> 25.582344
C9: 0.05 | D9: =(($G$21*(1+$C9)/(1+D$7)^1) +($G$21*(1+$C9)^2/(1+D$7)^2) +($G$21*(1+$C9)^3/(1+D$7)^3) +($G$21*(1+$C9)^4/(1+D$7)^4) +($G$21*(1+$C9)^5/(1+D$7)^5) +(($G$21*(1+$C9)^5*(1+$G$20)/(D$7-$G$20))/(1+D$7)^5) -$G$23) /$G$24 -> 57.260242 | E9: =(($G$21*(1+$C9)/(1+E$7)^1) +($G$21*(1+$C9)^2/(1+E$7)^2) +($G$21*(1+$C9)^3/(1+E$7)^3) +($G$21*(1+$C9)^4/(1+E$7)^4) +($G$21*(1+$C9)^5/(1+E$7)^5) +(($G$21*(1+$C9)^5*(1+$G$20)/(E$7-$G$20))/(1+E$7)^5) -$G$23) /$G$24 -> 48.569208 | F9: =(($G$21*(1+$C9)/(1+F$7)^1) +($G$21*(1+$C9)^2/(1+F$7)^2) +($G$21*(1+$C9)^3/(1+F$7)^3) +($G$21*(1+$C9)^4/(1+F$7)^4) +($G$21*(1+$C9)^5/(1+F$7)^5) +(($G$21*(1+$C9)^5*(1+$G$20)/(F$7-$G$20))/(1+F$7)^5) -$G$23) /$G$24 -> 42.051784 | G9: =(($G$21*(1+$C9)/(1+G$7)^1) +($G$21*(1+$C9)^2/(1+G$7)^2) +($G$21*(1+$C9)^3/(1+G$7)^3) +($G$21*(1+$C9)^4/(1+G$7)^4) +($G$21*(1+$C9)^5/(1+G$7)^5) +(($G$21*(1+$C9)^5*(1+$G$20)/(G$7-$G$20))/(1+G$7)^5) -$G$23) /$G$24 -> 36.983415 | H9: =(($G$21*(1+$C9)/(1+H$7)^1) +($G$21*(1+$C9)^2/(1+H$7)^2) +($G$21*(1+$C9)^3/(1+H$7)^3) +($G$21*(1+$C9)^4/(1+H$7)^4) +($G$21*(1+$C9)^5/(1+H$7)^5) +(($G$21*(1+$C9)^5*(1+$G$20)/(H$7-$G$20))/(1+H$7)^5) -$G$23) /$G$24 -> 32.929368 | I9: =(($G$21*(1+$C9)/(1+I$7)^1) +($G$21*(1+$C9)^2/(1+I$7)^2) +($G$21*(1+$C9)^3/(1+I$7)^3) +($G$21*(1+$C9)^4/(1+I$7)^4) +($G$21*(1+$C9)^5/(1+I$7)^5) +(($G$21*(1+$C9)^5*(1+$G$20)/(I$7-$G$20))/(1+I$7)^5) -$G$23) /$G$24 -> 29.612997 | J9: =(($G$21*(1+$C9)/(1+J$7)^1) +($G$21*(1+$C9)^2/(1+J$7)^2) +($G$21*(1+$C9)^3/(1+J$7)^3) +($G$21*(1+$C9)^4/(1+J$7)^4) +($G$21*(1+$C9)^5/(1+J$7)^5) +(($G$21*(1+$C9)^5*(1+$G$20)/(J$7-$G$20))/(1+J$7)^5) -$G$23) /$G$24 -> 26.849869
C10: 0.06 | D10: =(($G$21*(1+$C10)/(1+D$7)^1) +($G$21*(1+$C10)^2/(1+D$7)^2) +($G$21*(1+$C10)^3/(1+D$7)^3) +($G$21*(1+$C10)^4/(1+D$7)^4) +($G$21*(1+$C10)^5/(1+D$7)^5) +(($G$21*(1+$C10)^5*(1+$G$20)/(D$7-$G$20))/(1+D$7)^5) -$G$23) /$G$24 -> 60.041952 | E10: =(($G$21*(1+$C10)/(1+E$7)^1) +($G$21*(1+$C10)^2/(1+E$7)^2) +($G$21*(1+$C10)^3/(1+E$7)^3) +($G$21*(1+$C10)^4/(1+E$7)^4) +($G$21*(1+$C10)^5/(1+E$7)^5) +(($G$21*(1+$C10)^5*(1+$G$20)/(E$7-$G$20))/(1+E$7)^5) -$G$23) /$G$24 -> 50.93054 | F10: =(($G$21*(1+$C10)/(1+F$7)^1) +($G$21*(1+$C10)^2/(1+F$7)^2) +($G$21*(1+$C10)^3/(1+F$7)^3) +($G$21*(1+$C10)^4/(1+F$7)^4) +($G$21*(1+$C10)^5/(1+F$7)^5) +(($G$21*(1+$C10)^5*(1+$G$20)/(F$7-$G$20))/(1+F$7)^5) -$G$23) /$G$24 -> 44.098212 | G10: =(($G$21*(1+$C10)/(1+G$7)^1) +($G$21*(1+$C10)^2/(1+G$7)^2) +($G$21*(1+$C10)^3/(1+G$7)^3) +($G$21*(1+$C10)^4/(1+G$7)^4) +($G$21*(1+$C10)^5/(1+G$7)^5) +(($G$21*(1+$C10)^5*(1+$G$20)/(G$7-$G$20))/(1+G$7)^5) -$G$23) /$G$24 -> 38.785245 | H10: =(($G$21*(1+$C10)/(1+H$7)^1) +($G$21*(1+$C10)^2/(1+H$7)^2) +($G$21*(1+$C10)^3/(1+H$7)^3) +($G$21*(1+$C10)^4/(1+H$7)^4) +($G$21*(1+$C10)^5/(1+H$7)^5) +(($G$21*(1+$C10)^5*(1+$G$20)/(H$7-$G$20))/(1+H$7)^5) -$G$23) /$G$24 -> 34.535808 | I10: =(($G$21*(1+$C10)/(1+I$7)^1) +($G$21*(1+$C10)^2/(1+I$7)^2) +($G$21*(1+$C10)^3/(1+I$7)^3) +($G$21*(1+$C10)^4/(1+I$7)^4) +($G$21*(1+$C10)^5/(1+I$7)^5) +(($G$21*(1+$C10)^5*(1+$G$20)/(I$7-$G$20))/(1+I$7)^5) -$G$23) /$G$24 -> 31.059827 | J10: =(($G$21*(1+$C10)/(1+J$7)^1) +($G$21*(1+$C10)^2/(1+J$7)^2) +($G$21*(1+$C10)^3/(1+J$7)^3) +($G$21*(1+$C10)^4/(1+J$7)^4) +($G$21*(1+$C10)^5/(1+J$7)^5) +(($G$21*(1+$C10)^5*(1+$G$20)/(J$7-$G$20))/(1+J$7)^5) -$G$23) /$G$24 -> 28.16392
C11: 0.07 | D11: =(($G$21*(1+$C11)/(1+D$7)^1) +($G$21*(1+$C11)^2/(1+D$7)^2) +($G$21*(1+$C11)^3/(1+D$7)^3) +($G$21*(1+$C11)^4/(1+D$7)^4) +($G$21*(1+$C11)^5/(1+D$7)^5) +(($G$21*(1+$C11)^5*(1+$G$20)/(D$7-$G$20))/(1+D$7)^5) -$G$23) /$G$24 -> 62.927736 | E11: =(($G$21*(1+$C11)/(1+E$7)^1) +($G$21*(1+$C11)^2/(1+E$7)^2) +($G$21*(1+$C11)^3/(1+E$7)^3) +($G$21*(1+$C11)^4/(1+E$7)^4) +($G$21*(1+$C11)^5/(1+E$7)^5) +(($G$21*(1+$C11)^5*(1+$G$20)/(E$7-$G$20))/(1+E$7)^5) -$G$23) /$G$24 -> 53.379817 | F11: =(($G$21*(1+$C11)/(1+F$7)^1) +($G$21*(1+$C11)^2/(1+F$7)^2) +($G$21*(1+$C11)^3/(1+F$7)^3) +($G$21*(1+$C11)^4/(1+F$7)^4) +($G$21*(1+$C11)^5/(1+F$7)^5) +(($G$21*(1+$C11)^5*(1+$G$20)/(F$7-$G$20))/(1+F$7)^5) -$G$23) /$G$24 -> 46.220507 | G11: =(($G$21*(1+$C11)/(1+G$7)^1) +($G$21*(1+$C11)^2/(1+G$7)^2) +($G$21*(1+$C11)^3/(1+G$7)^3) +($G$21*(1+$C11)^4/(1+G$7)^4) +($G$21*(1+$C11)^5/(1+G$7)^5) +(($G$21*(1+$C11)^5*(1+$G$20)/(G$7-$G$20))/(1+G$7)^5) -$G$23) /$G$24 -> 40.653569 | H11: =(($G$21*(1+$C11)/(1+H$7)^1) +($G$21*(1+$C11)^2/(1+H$7)^2) +($G$21*(1+$C11)^3/(1+H$7)^3) +($G$21*(1+$C11)^4/(1+H$7)^4) +($G$21*(1+$C11)^5/(1+H$7)^5) +(($G$21*(1+$C11)^5*(1+$G$20)/(H$7-$G$20))/(1+H$7)^5) -$G$23) /$G$24 -> 36.201261 | I11: =(($G$21*(1+$C11)/(1+I$7)^1) +($G$21*(1+$C11)^2/(1+I$7)^2) +($G$21*(1+$C11)^3/(1+I$7)^3) +($G$21*(1+$C11)^4/(1+I$7)^4) +($G$21*(1+$C11)^5/(1+I$7)^5) +(($G$21*(1+$C11)^5*(1+$G$20)/(I$7-$G$20))/(1+I$7)^5) -$G$23) /$G$24 -> 32.559564 | J11: =(($G$21*(1+$C11)/(1+J$7)^1) +($G$21*(1+$C11)^2/(1+J$7)^2) +($G$21*(1+$C11)^3/(1+J$7)^3) +($G$21*(1+$C11)^4/(1+J$7)^4) +($G$21*(1+$C11)^5/(1+J$7)^5) +(($G$21*(1+$C11)^5*(1+$G$20)/(J$7-$G$20))/(1+J$7)^5) -$G$23) /$G$24 -> 29.525801
C12: 0.075 | D12: =(($G$21*(1+$C12)/(1+D$7)^1) +($G$21*(1+$C12)^2/(1+D$7)^2) +($G$21*(1+$C12)^3/(1+D$7)^3) +($G$21*(1+$C12)^4/(1+D$7)^4) +($G$21*(1+$C12)^5/(1+D$7)^5) +(($G$21*(1+$C12)^5*(1+$G$20)/(D$7-$G$20))/(1+D$7)^5) -$G$23) /$G$24 -> 64.410571 | E12: =(($G$21*(1+$C12)/(1+E$7)^1) +($G$21*(1+$C12)^2/(1+E$7)^2) +($G$21*(1+$C12)^3/(1+E$7)^3) +($G$21*(1+$C12)^4/(1+E$7)^4) +($G$21*(1+$C12)^5/(1+E$7)^5) +(($G$21*(1+$C12)^5*(1+$G$20)/(E$7-$G$20))/(1+E$7)^5) -$G$23) /$G$24 -> 54.638205 | F12: =(($G$21*(1+$C12)/(1+F$7)^1) +($G$21*(1+$C12)^2/(1+F$7)^2) +($G$21*(1+$C12)^3/(1+F$7)^3) +($G$21*(1+$C12)^4/(1+F$7)^4) +($G$21*(1+$C12)^5/(1+F$7)^5) +(($G$21*(1+$C12)^5*(1+$G$20)/(F$7-$G$20))/(1+F$7)^5) -$G$23) /$G$24 -> 47.310769 | G12: =(($G$21*(1+$C12)/(1+G$7)^1) +($G$21*(1+$C12)^2/(1+G$7)^2) +($G$21*(1+$C12)^3/(1+G$7)^3) +($G$21*(1+$C12)^4/(1+G$7)^4) +($G$21*(1+$C12)^5/(1+G$7)^5) +(($G$21*(1+$C12)^5*(1+$G$20)/(G$7-$G$20))/(1+G$7)^5) -$G$23) /$G$24 -> 41.613247 | H12: =(($G$21*(1+$C12)/(1+H$7)^1) +($G$21*(1+$C12)^2/(1+H$7)^2) +($G$21*(1+$C12)^3/(1+H$7)^3) +($G$21*(1+$C12)^4/(1+H$7)^4) +($G$21*(1+$C12)^5/(1+H$7)^5) +(($G$21*(1+$C12)^5*(1+$G$20)/(H$7-$G$20))/(1+H$7)^5) -$G$23) /$G$24 -> 37.05663 | I12: =(($G$21*(1+$C12)/(1+I$7)^1) +($G$21*(1+$C12)^2/(1+I$7)^2) +($G$21*(1+$C12)^3/(1+I$7)^3) +($G$21*(1+$C12)^4/(1+I$7)^4) +($G$21*(1+$C12)^5/(1+I$7)^5) +(($G$21*(1+$C12)^5*(1+$G$20)/(I$7-$G$20))/(1+I$7)^5) -$G$23) /$G$24 -> 33.329731 | J12: =(($G$21*(1+$C12)/(1+J$7)^1) +($G$21*(1+$C12)^2/(1+J$7)^2) +($G$21*(1+$C12)^3/(1+J$7)^3) +($G$21*(1+$C12)^4/(1+J$7)^4) +($G$21*(1+$C12)^5/(1+J$7)^5) +(($G$21*(1+$C12)^5*(1+$G$20)/(J$7-$G$20))/(1+J$7)^5) -$G$23) /$G$24 -> 30.225093
C13: 0.08 | D13: =(($G$21*(1+$C13)/(1+D$7)^1) +($G$21*(1+$C13)^2/(1+D$7)^2) +($G$21*(1+$C13)^3/(1+D$7)^3) +($G$21*(1+$C13)^4/(1+D$7)^4) +($G$21*(1+$C13)^5/(1+D$7)^5) +(($G$21*(1+$C13)^5*(1+$G$20)/(D$7-$G$20))/(1+D$7)^5) -$G$23) /$G$24 -> 65.920529 | E13: =(($G$21*(1+$C13)/(1+E$7)^1) +($G$21*(1+$C13)^2/(1+E$7)^2) +($G$21*(1+$C13)^3/(1+E$7)^3) +($G$21*(1+$C13)^4/(1+E$7)^4) +($G$21*(1+$C13)^5/(1+E$7)^5) +(($G$21*(1+$C13)^5*(1+$G$20)/(E$7-$G$20))/(1+E$7)^5) -$G$23) /$G$24 -> 55.919509 | F13: =(($G$21*(1+$C13)/(1+F$7)^1) +($G$21*(1+$C13)^2/(1+F$7)^2) +($G$21*(1+$C13)^3/(1+F$7)^3) +($G$21*(1+$C13)^4/(1+F$7)^4) +($G$21*(1+$C13)^5/(1+F$7)^5) +(($G$21*(1+$C13)^5*(1+$G$20)/(F$7-$G$20))/(1+F$7)^5) -$G$23) /$G$24 -> 48.420798 | G13: =(($G$21*(1+$C13)/(1+G$7)^1) +($G$21*(1+$C13)^2/(1+G$7)^2) +($G$21*(1+$C13)^3/(1+G$7)^3) +($G$21*(1+$C13)^4/(1+G$7)^4) +($G$21*(1+$C13)^5/(1+G$7)^5) +(($G$21*(1+$C13)^5*(1+$G$20)/(G$7-$G$20))/(1+G$7)^5) -$G$23) /$G$24 -> 42.590248 | H13: =(($G$21*(1+$C13)/(1+H$7)^1) +($G$21*(1+$C13)^2/(1+H$7)^2) +($G$21*(1+$C13)^3/(1+H$7)^3) +($G$21*(1+$C13)^4/(1+H$7)^4) +($G$21*(1+$C13)^5/(1+H$7)^5) +(($G$21*(1+$C13)^5*(1+$G$20)/(H$7-$G$20))/(1+H$7)^5) -$G$23) /$G$24 -> 37.927372 | I13: =(($G$21*(1+$C13)/(1+I$7)^1) +($G$21*(1+$C13)^2/(1+I$7)^2) +($G$21*(1+$C13)^3/(1+I$7)^3) +($G$21*(1+$C13)^4/(1+I$7)^4) +($G$21*(1+$C13)^5/(1+I$7)^5) +(($G$21*(1+$C13)^5*(1+$G$20)/(I$7-$G$20))/(1+I$7)^5) -$G$23) /$G$24 -> 34.113679 | J13: =(($G$21*(1+$C13)/(1+J$7)^1) +($G$21*(1+$C13)^2/(1+J$7)^2) +($G$21*(1+$C13)^3/(1+J$7)^3) +($G$21*(1+$C13)^4/(1+J$7)^4) +($G$21*(1+$C13)^5/(1+J$7)^5) +(($G$21*(1+$C13)^5*(1+$G$20)/(J$7-$G$20))/(1+J$7)^5) -$G$23) /$G$24 -> 30.936842
C14: 0.09 | D14: =(($G$21*(1+$C14)/(1+D$7)^1) +($G$21*(1+$C14)^2/(1+D$7)^2) +($G$21*(1+$C14)^3/(1+D$7)^3) +($G$21*(1+$C14)^4/(1+D$7)^4) +($G$21*(1+$C14)^5/(1+D$7)^5) +(($G$21*(1+$C14)^5*(1+$G$20)/(D$7-$G$20))/(1+D$7)^5) -$G$23) /$G$24 -> 69.023318 | E14: =(($G$21*(1+$C14)/(1+E$7)^1) +($G$21*(1+$C14)^2/(1+E$7)^2) +($G$21*(1+$C14)^3/(1+E$7)^3) +($G$21*(1+$C14)^4/(1+E$7)^4) +($G$21*(1+$C14)^5/(1+E$7)^5) +(($G$21*(1+$C14)^5*(1+$G$20)/(E$7-$G$20))/(1+E$7)^5) -$G$23) /$G$24 -> 58.552135 | F14: =(($G$21*(1+$C14)/(1+F$7)^1) +($G$21*(1+$C14)^2/(1+F$7)^2) +($G$21*(1+$C14)^3/(1+F$7)^3) +($G$21*(1+$C14)^4/(1+F$7)^4) +($G$21*(1+$C14)^5/(1+F$7)^5) +(($G$21*(1+$C14)^5*(1+$G$20)/(F$7-$G$20))/(1+F$7)^5) -$G$23) /$G$24 -> 50.70125 | G14: =(($G$21*(1+$C14)/(1+G$7)^1) +($G$21*(1+$C14)^2/(1+G$7)^2) +($G$21*(1+$C14)^3/(1+G$7)^3) +($G$21*(1+$C14)^4/(1+G$7)^4) +($G$21*(1+$C14)^5/(1+G$7)^5) +(($G$21*(1+$C14)^5*(1+$G$20)/(G$7-$G$20))/(1+G$7)^5) -$G$23) /$G$24 -> 44.597176 | H14: =(($G$21*(1+$C14)/(1+H$7)^1) +($G$21*(1+$C14)^2/(1+H$7)^2) +($G$21*(1+$C14)^3/(1+H$7)^3) +($G$21*(1+$C14)^4/(1+H$7)^4) +($G$21*(1+$C14)^5/(1+H$7)^5) +(($G$21*(1+$C14)^5*(1+$G$20)/(H$7-$G$20))/(1+H$7)^5) -$G$23) /$G$24 -> 39.715821 | I14: =(($G$21*(1+$C14)/(1+I$7)^1) +($G$21*(1+$C14)^2/(1+I$7)^2) +($G$21*(1+$C14)^3/(1+I$7)^3) +($G$21*(1+$C14)^4/(1+I$7)^4) +($G$21*(1+$C14)^5/(1+I$7)^5) +(($G$21*(1+$C14)^5*(1+$G$20)/(I$7-$G$20))/(1+I$7)^5) -$G$23) /$G$24 -> 35.723674 | J14: =(($G$21*(1+$C14)/(1+J$7)^1) +($G$21*(1+$C14)^2/(1+J$7)^2) +($G$21*(1+$C14)^3/(1+J$7)^3) +($G$21*(1+$C14)^4/(1+J$7)^4) +($G$21*(1+$C14)^5/(1+J$7)^5) +(($G$21*(1+$C14)^5*(1+$G$20)/(J$7-$G$20))/(1+J$7)^5) -$G$23) /$G$24 -> 32.398397
C15: 0.1 | D15: =(($G$21*(1+$C15)/(1+D$7)^1) +($G$21*(1+$C15)^2/(1+D$7)^2) +($G$21*(1+$C15)^3/(1+D$7)^3) +($G$21*(1+$C15)^4/(1+D$7)^4) +($G$21*(1+$C15)^5/(1+D$7)^5) +(($G$21*(1+$C15)^5*(1+$G$20)/(D$7-$G$20))/(1+D$7)^5) -$G$23) /$G$24 -> 72.239144 | E15: =(($G$21*(1+$C15)/(1+E$7)^1) +($G$21*(1+$C15)^2/(1+E$7)^2) +($G$21*(1+$C15)^3/(1+E$7)^3) +($G$21*(1+$C15)^4/(1+E$7)^4) +($G$21*(1+$C15)^5/(1+E$7)^5) +(($G$21*(1+$C15)^5*(1+$G$20)/(E$7-$G$20))/(1+E$7)^5) -$G$23) /$G$24 -> 61.280261 | F15: =(($G$21*(1+$C15)/(1+F$7)^1) +($G$21*(1+$C15)^2/(1+F$7)^2) +($G$21*(1+$C15)^3/(1+F$7)^3) +($G$21*(1+$C15)^4/(1+F$7)^4) +($G$21*(1+$C15)^5/(1+F$7)^5) +(($G$21*(1+$C15)^5*(1+$G$20)/(F$7-$G$20))/(1+F$7)^5) -$G$23) /$G$24 -> 53.064073 | G15: =(($G$21*(1+$C15)/(1+G$7)^1) +($G$21*(1+$C15)^2/(1+G$7)^2) +($G$21*(1+$C15)^3/(1+G$7)^3) +($G$21*(1+$C15)^4/(1+G$7)^4) +($G$21*(1+$C15)^5/(1+G$7)^5) +(($G$21*(1+$C15)^5*(1+$G$20)/(G$7-$G$20))/(1+G$7)^5) -$G$23) /$G$24 -> 46.676283 | H15: =(($G$21*(1+$C15)/(1+H$7)^1) +($G$21*(1+$C15)^2/(1+H$7)^2) +($G$21*(1+$C15)^3/(1+H$7)^3) +($G$21*(1+$C15)^4/(1+H$7)^4) +($G$21*(1+$C15)^5/(1+H$7)^5) +(($G$21*(1+$C15)^5*(1+$G$20)/(H$7-$G$20))/(1+H$7)^5) -$G$23) /$G$24 -> 41.568315 | I15: =(($G$21*(1+$C15)/(1+I$7)^1) +($G$21*(1+$C15)^2/(1+I$7)^2) +($G$21*(1+$C15)^3/(1+I$7)^3) +($G$21*(1+$C15)^4/(1+I$7)^4) +($G$21*(1+$C15)^5/(1+I$7)^5) +(($G$21*(1+$C15)^5*(1+$G$20)/(I$7-$G$20))/(1+I$7)^5) -$G$23) /$G$24 -> 37.391078 | J15: =(($G$21*(1+$C15)/(1+J$7)^1) +($G$21*(1+$C15)^2/(1+J$7)^2) +($G$21*(1+$C15)^3/(1+J$7)^3) +($G$21*(1+$C15)^4/(1+J$7)^4) +($G$21*(1+$C15)^5/(1+J$7)^5) +(($G$21*(1+$C15)^5*(1+$G$20)/(J$7-$G$20))/(1+J$7)^5) -$G$23) /$G$24 -> 33.911843
B20: Terminal Growth Rate | G20: 0.025
B21: Base FCF | G21: ='Raw Data'!H16-'Raw Data'!H17 -> 12660
B22: Implied Share Price (FY2025 Base) | G22: ='Ratios & Calculations'!C63/'Ratios & Calculations'!C39 -> 43.780117
B23: Net Debt | G23: ='Raw Data'!H15-'Raw Data'!H21 -> 25747
B24: Shares Outstanding | G24: 8017
B25: *Calculations in bold font

Sheet YoY Growth
B2: WALMART INC. | Year-Over-Year Growth Analysis
B4: YoY change = (Current Year - Prior Year) / Prior Year | CAGR = (End/Start)^(1/n)-1
B6: Metric | C6: 2020-21 | D6: 2021-22 | E6: 2022-23 | F6: 2023-24 | G6: 2024-25 | H6: 5-Yr CAGR
B7: ($mm)
B8: Revenue | C8: =('Raw Data'!D8-'Raw Data'!C8)/'Raw Data'!C8 -> 0.067155377 | D8: =('Raw Data'!E8-'Raw Data'!D8)/'Raw Data'!D8 -> 0.024327954 | E8: =('Raw Data'!F8-'Raw Data'!E8)/'Raw Data'!E8 -> 0.067280194 | F8: =('Raw Data'!G8-'Raw Data'!F8)/'Raw Data'!F8 -> 0.06025955 | G8: =('Raw Data'!H8-'Raw Data'!G8)/'Raw Data'!G8 -> 0.050700096 | H8: =('Raw Data'!H8/'Raw Data'!C8)^(1/5)-1 -> 0.053821899
B9: Operating Income | C9: =('Raw Data'!D11-'Raw Data'!C11)/'Raw Data'!C11 -> 0.096266044 | D9: =('Raw Data'!E11-'Raw Data'!D11)/'Raw Data'!D11 -> 0.15052333 | E9: =('Raw Data'!F11-'Raw Data'!E11)/'Raw Data'!E11 -> -0.21255108 | F9: =('Raw Data'!G11-'Raw Data'!F11)/'Raw Data'!F11 -> 0.32230272 | G9: =('Raw Data'!H11-'Raw Data'!G11)/'Raw Data'!G11 -> 0.086480083 | H9: =('Raw Data'!H11/'Raw Data'!C11)^(1/5)-1 -> 0.073685998
B10: Net Income | C10: =('Raw Data'!D12-'Raw Data'!C12)/'Raw Data'!C12 -> -0.098348793 | D10: =('Raw Data'!E12-'Raw Data'!D12)/'Raw Data'!D12 -> 0.017072815 | E10: =('Raw Data'!F12-'Raw Data'!E12)/'Raw Data'!E12 -> -0.18995696 | F10: =('Raw Data'!G12-'Raw Data'!F12)/'Raw Data'!F12 -> 0.44084307 | G10: =('Raw Data'!H12-'Raw Data'!G12)/'Raw Data'!G12 -> 0.23890596 | H10: =('Raw Data'!H12/'Raw Data'!C12)^(1/5)-1 -> 0.058061099
B11: Gross Profit | C11: =('Raw Data'!D10-'Raw Data'!C10)/'Raw Data'!C10 -> 0.073261234 | D11: =('Raw Data'!E10-'Raw Data'!D10)/'Raw Data'!D10 -> 0.035423089 | E11: =('Raw Data'!F10-'Raw Data'!E10)/'Raw Data'!E10 -> 0.026531436 | F11: =('Raw Data'!G10-'Raw Data'!F10)/'Raw Data'!F10 -> 0.08619755 | G11: =('Raw Data'!H10-'Raw Data'!G10)/'Raw Data'!G10 -> 0.058719305 | H11: =('Raw Data'!H10/'Raw Data'!C10)^(1/5)-1 -> 0.055788771
B13: *Calculations in bold font
B15: Key Observation

Sheet Peer Comparisons
B2: PEER COMPARISON | FY2025 Benchmarking
B4: Sources: Walmart 10-K (2025), Target 10-K (2025), Kroger 10-K (2025)
B6: Metric | C6: Walmart | D6: Target | E6: Kroger
B8: Revenue ($mm) | C8: 680985 | D8: 109409 | E8: 147642
B9: Gross Profit ($mm) | C9: 169700 | D9: 31190 | E9: 34402
B10: Operating Income ($mm) | C10: 29348 | D10: 5628 | E10: 1890
B11: Net Income ($mm) | C11: 20157 | D11: 4138 | E11: 1016
B12: Gross Margin | C12: =C9/C8 -> 0.24919785 | D12: =D9/D8 -> 0.2850771 | E12: =E9/E8 -> 0.23300958
B13: Operating Margin | C13: =C10/C8 -> 0.043096397 | D13: =D10/D8 -> 0.05144001 | E13: =E10/E8 -> 0.012801235
B14: Net Margin | C14: =C11/C8 -> 0.029599771 | D14: =D11/D8 -> 0.037821386 | E14: =E11/E8 -> 0.0068815107
B15: Total Assets ($mm) | C15: 260649 | D15: 55356 | E15: 52616
B16: Return on Assets (ROA) | C16: =C11/C15 -> 0.077333886 | D16: =D11/D15 -> 0.074752511 | E16: =E11/E15 -> 0.019309716
B17: Total Equity ($mm) | C17: 98123 | D17: 11327 | E17: 8285
B18: Return on Equity (ROE) | C18: =C11/C17 -> 0.20542584 | D18: =D11/D17 -> 0.3653218 | E18: =E11/E17 -> 0.12263126
B20: *Calculations in bold font
B22: Comparison Summary

Sheet Insight
B2: ANALYST INSIGHTS
B4: REVENUE GROWTH
B11: PROFITABILITY TRENDS
B20: MARGIN ANALYSIS
B28: BALANCE SHEET STRENGTH
B35: PEER POSITIONING
B42: INVESTMENT CONSIDERATIONS
B48: DCF Valuation Analysis

Sheet Dashboard
B5: FY2025
B6: Revenue | C6: Net Income | D6: Op. Margin | E6: Net Margin | F6: ROE | G6: 5-Yr Rev CAGR | I6: Implied Share Price | J6: Current Market Price | K6: Upside/Downside | L6: WACC
B7: ='Raw Data'!H8 -> 680985 | C7: ='Raw Data'!H12 -> 20157 | D7: ='Ratios & Calculations'!H10 -> 0.043096397 | E7: ='Ratios & Calculations'!H11 -> 0.029599771 | F7: ='Ratios & Calculations'!H14 -> 0.35449385 | G7: ='YoY Growth'!H8 -> 0.053821899 | I7: ='Ratios & Calculations'!C64 -> 43.780117 | J7: ='Ratios & Calculations'!C65 -> 114.75 | K7: ='Ratios & Calculations'!C66 -> -0.61847393 | L7: ='Ratios & Calculations'!C43 -> 0.067957618
B43: Source: Walmart Annual Reports (10-K Filings) | All values in USD millions | Created June 2026
B46: DCF Valuation Summary
